Workbook

Sheet ReadMe

Sheet Data
A1: Name of Farm | B1: Sample ID | C1: Date | D1: Status | E1: Status Analysis | F1: What is produced | G1: What is produced spesific | H1: Weight Soil Dry [g] (added to beaker) | I1: Nile Red | K1: Weather | N1: Location | R1: Notes - Environment description
I2: Manual counted Plastic [n/5g] | J2: Data Program Counted Plastic [n/5g] | K2: Weather | L2: Total Rain 24h | M2: Avg. Temperature last 24h | N2: Kjøreplan | O2: Kommuner | P2: Longitude | Q2: Latitude
A3: Voll Gård | B3: 1.1 | C3: 06.24.2026 14:15 | D3: Finished | E3: Finished Nile Red | F3: Gress | G3: Gress | H3: 5.01 | I3: 1 | J3: 3 | K3: Rainy | L3: 4.5 | M3: 12.3 | N3: Trondheim | O3: Trondheim | R3: No visible plastic waste
A4: Voll Gård | B4: 1.2 | C4: 06.24.2026 14:30 | D4: Finished | E4: Finished Nile Red | F4: Beite | G4: Geit | H4: 5.02 | I4: 1 | J4: 1 | K4: Rainy | L4: 4.5 | M4: 12.3 | N4: Trondheim | O4: Trondheim | R4: No visible plastic waste
A5: Onsøyen Gård | B5: 2.1 | C5: 07.01.2026 07:31 | D5: Finished | E5: Finished Nile Red | F5: Gress | G5: Gress | H5: 5.1 | I5: 3 | J5: 3 | K5: sunny | L5: 0 | M5: 14.6 | N5: Spongdal | O5: Trondheim | P5: 10.18236 | Q5: 63.42836 | R5: Høyballer, gård, parkeringsplass, veg, elv, skog, agriculture machine, traktor veg
A6: Onsøyen Gård | B6: 2.2 | C6: 07.01.2026 07:39 | D6: Finished | E6: Finished Nile Red | F6: Beite | G6: Sau | H6: 5.08 | I6: 3 | J6: 96 | K6: sunny | L6: 0 | M6: 14.6 | N6: Spongdal | O6: Trondheim | P6: 10.18236 | Q6: 63.42836 | R6: Høyballer, gård, parkeringsplass, veg, elv, skog, agriculture machine, traktor veg
A7: Onsøyen Gård | B7: 2.3 | C7: 07.01.2026 07:58 | D7: Finished | E7: Finished Nile Red | F7: Korn | G7: Bygg | H7: 5.01 | I7: 5 | J7: 6 | K7: sunny | L7: 0 | M7: 14.6 | N7: Spongdal | O7: Trondheim | P7: 10.18236 | Q7: 63.42836 | R7: Høyballer, gård, parkeringsplass, veg, elv, skog, agriculture machine, traktor veg
A8: Onsøyen Gård | B8: 2.4 | C8: 07.01.2026 08:23 | D8: Finished | E8: Finished Nile Red | F8: Gress | G8: Gress | H8: 5.01 | I8: 2 | J8: 2 | K8: sunny | L8: 0 | M8: 14.6 | N8: Spongdal | O8: Trondheim | P8: 10.18236 | Q8: 63.42836 | R8: Høyballer, gård, parkeringsplass, veg, elv, skog, agriculture machine, traktor veg
A9: Frøset Østre | B9: 3.1 | C9: 07.01.2026 10:35 | D9: Finished | E9: Finished Nile Red | F9: Gress | G9: Gress | H9: 4.99 | I9: 0 | J9: 0 | K9: sunny | L9: 0 | M9: 14.6 | N9: Spongdal | O9: Trondheim | P9: 10.10738 | Q9: 63.42074 | R9: Coast, main road, houses,
A10: Frøset Østre | B10: 3.2 | C10: 07.01.2026 10:40 | D10: Finished | E10: Finished Nile Red | F10: Gress | G10: Gress | H10: 5 | I10: 2 | J10: 2 | K10: sunny | L10: 0 | M10: 14.6 | N10: Spongdal | O10: Trondheim | P10: 10.10738 | Q10: 63.42074 | R10: Coast, main road, houses,
A11: Hangerslettvegen 605 | B11: 4.1 | C11: 07.01.2026 11:40 | D11: Finished | E11: Finished Nile Red | F11: Gress | G11: Gress | H11: 5 | I11: 0 | J11: 0 | K11: sunny | L11: 0 | M11: 14.6 | N11: Spongdal | O11: Trondheim | P11: 10.06796 | Q11: 63.39483 | R11: Ocean, slope, field equipment, housing
A12: Hangerslettvegen 605 | B12: 4.2 | C12: 07.01.2026 11:53 | D12: Finished | E12: Finished Nile Red | F12: Gress | G12: Gress | H12: 5.02 | I12: 1 | J12: 1 | K12: sunny | L12: 0 | M12: 14.6 | N12: Spongdal | O12: Trondheim | P12: 10.06796 | Q12: 63.39483 | R12: Ocean, slope, field equipment, housing
A13: Ålberg Gård | B13: 5.1 | C13: 07.01.2026 12:24 | D13: Finished | E13: Finished Nile Red | F13: Korn | G13: Bygg | H13: 5.02 | I13: 3 | J13: 3 | K13: sunny | L13: 0 | M13: 14.6 | N13: Spongdal | O13: Trondheim | P13: 10.12815 | Q13: 63.36554 | R13: Van site, road, hill, vedpose
A14: Ålberg Gård | B14: 5.2 | C14: 07.01.2026 12:36 | D14: Finished | E14: Finished Nile Red | F14: Korn | G14: Bygg | H14: 5 | I14: 2 | J14: 2 | K14: sunny | L14: 0 | M14: 14.6 | N14: Spongdal | O14: Trondheim | P14: 10.12815 | Q14: 63.36554 | R14: Van site, road, hill, vedpose
A15: Snusbonden | B15: 6.1 | C15: 07.01.2026 09:39 | D15: Finished | E15: Finished Nile Red | F15: Korn | G15: Korn | H15: 5.05 | I15: 2 | J15: 2 | K15: sunny | L15: 0 | M15: 14.6 | N15: Spongdal | O15: Trondheim | P15: 10.14913 | Q15: 63.40905 | R15: Agriculture mchines, skog, gravel driveway
A16: Snusbonden | B16: 6.2 | C16: 07.01.2026 09:47 | D16: Finished | E16: Finished Nile Red | F16: Other | G16: Tobakk | H16: 4.99 | I16: 3 | J16: 3 | K16: sunny | L16: 0 | M16: 14.6 | N16: Spongdal | O16: Trondheim | P16: 10.14913 | Q16: 63.40905 | R16: Agriculture mchines, skog, gravel driveway
... A27: Spongdalsvegen 473 (oppland gård) | B27: 9.4 | C27: 07.01.2026 10:07 | D27: Finished | E27: Finished Nile Red | F27: Korn | G27: Bygg | H27: 5 | I27: 0 | J27: 0 | K27: sunny | L27: 0 | M27: 14.6 | N27: Spongdal | O27: Trondheim | P27: 10.15114 | Q27: 63.38321 | R27: Vei, traktor, vedskjul, høyballplastrull, skog
A28: Plantasjen | B28: 10.1 | C28: 07.02.2026 12:09 | D28: Finished | E28: Finished Nile Red | F28: Other | G28: Pose med jord | H28: 5 | I28: 13 | J28: 0 | N28: Other | P28: 10.45153 | Q28: 63.43169 | R28: Jord fra posene man får kjøpt på Plantasjen, med hull i
A29: Plantasjen | B29: 10.2 | C29: 07.02.2026 12:32 | D29: Finished | E29: Finished Nile Red | F29: Other | G29: Jord fra planter man kan kjøpe: Eple, Rabarbara, Hageblåbær, Bringebær, Rips, Kruspersille, Citronmelisse, Timian, Rosmarin, Snack Paprika, Rød Chili, Cherry tomat, cocktailtomat | H29: 4.99 | I29: 0 | J29: 0 | N29: Other | P29: 10.45153 | Q29: 63.43169 | R29: Jord fra posene man får kjøpt på Plantasjen, med hull i
A30: Leander Lysklett | B30: 11.1 | C30: 07.03.2026 06:53 | D30: Finished | E30: Finished Nile Red | F30: Gress | G30: Gress | H30: 4.99 | I30: 0 | J30: 0 | L30: 0 | M30: 12.8 | N30: Klæbu | O30: Trondheim | P30: 10.48339 | Q30: 63.32817 | R30: Bilvei, låve, skog, høyballer,
A31: Leander Lysklett | B31: 11.2 | C31: 07.03.2026 07:16 | D31: Finished | E31: Finished Nile Red | F31: Gress | G31: Gress | H31: 5.01 | I31: 1 | J31: 1 | L31: 0 | M31: 12.8 | N31: Klæbu | O31: Trondheim | P31: 10.48339 | Q31: 63.32817 | R31: Bilvei, låve, skog, høyballer,
A32: Leander Lysklett | B32: 11.3 | C32: 07.03.2026 07:25 | D32: Finished | E32: Finished Nile Red | F32: Gress | G32: Gress | H32: 5.04 | I32: 5 | J32: 5 | L32: 0 | M32: 12.8 | N32: Klæbu | O32: Trondheim | P32: 10.48339 | Q32: 63.32817 | R32: Bilvei, låve, skog, høyballer,
A33: Leander Lysklett | B33: 11.4 | C33: 07.03.2026 07:45 | D33: Finished | E33: Finished Nile Red | F33: Gress | G33: Gress | H33: 5.03 | I33: 0 | J33: 0 | L33: 0 | M33: 12.8 | N33: Klæbu | O33: Trondheim | P33: 10.48339 | Q33: 63.32817 | R33: Bilvei, låve, skog, høyballer,
A34: Vangsmo | B34: 12.1 | C34: 07.03.2026 07:55 | D34: Filtered | F34: Korn | G34: Bygg | H34: 5.03 | L34: 0 | M34: 12.8 | N34: Klæbu | O34: Trondheim | P34: 10.47241 | Q34: 63.3202 | R34: Bilvei 80km, grusvei, gård, skog, høyspenningsmast
A35: Vangsmo | B35: 12.2 | C35: 07.03.2026 08:05 | D35: Finished | E35: Finished Nile Red | F35: Korn | G35: Bygg | H35: 5.02 | I35: 0 | J35: 0 | L35: 0 | M35: 12.8 | N35: Klæbu | O35: Trondheim | P35: 10.47241 | Q35: 63.3202 | R35: Bilvei 80km, grusvei, gård, skog, høyspenningsmast
A36: Vangsmo | B36: 12.3 | C36: 07.03.2026 08:08 | D36: Finished | E36: Finished Nile Red | F36: Korn | G36: Bygg | H36: 5 | I36: 1 | J36: 1 | L36: 0 | M36: 12.8 | N36: Klæbu | O36: Trondheim | P36: 10.47241 | Q36: 63.3202 | R36: Bilvei 80km, grusvei, gård, skog, høyspenningsmast
A37: Vangsmo | B37: 12.4 | C37: 07.03.2026 07:59 | D37: Finished | E37: Finished Nile Red | F37: Gress | G37: Gress på myr | H37: 5.01 | I37: 0 | J37: 0 | L37: 0 | M37: 12.8 | N37: Klæbu | O37: Trondheim | P37: 10.47241 | Q37: 63.3202 | R37: Bilvei 80km, grusvei, gård, skog, høyspenningsmast
A38: Christine Bertelsen | B38: 13.1 | C38: 07.03.2026 07:16 | D38: Finished | E38: Finished Nile Red | F38: Beite | G38: Hest | H38: 5 | I38: 0 | J38: 0 | L38: 0 | M38: 12.8 | N38: Klæbu | O38: Trondheim | P38: 10.46474 | Q38: 63.31809 | R38: Gjerde, skog, hest, traktorvei, strømmast
A39: Christine Bertelsen | B39: 13.2 | C39: 07.03.2026 07:24 | D39: Finished | E39: Finished Nile Red | F39: Gress | G39: Skogsjord | H39: 5.02 | I39: 0 | J39: 0 | L39: 0 | M39: 12.8 | N39: Klæbu | O39: Trondheim | P39: 10.46474 | Q39: 63.31809 | R39: Gjerde, skog, hest, traktorvei, strømmast
A40: Christine Bertelsen | B40: 13.3 | C40: 07.03.2026 07:32 | D40: Finished | E40: Finished Nile Red | F40: Gress | G40: Skogsjord | H40: 5.01 | I40: 1 | J40: 1 | L40: 0 | M40: 12.8 | N40: Klæbu | O40: Trondheim | P40: 10.46474 | Q40: 63.31809 | R40: Gjerde, skog, hest, traktorvei, strømmast
A41: Jonettaplassen Gårdsbarnehage | B41: 14.1 | C41: 07.03.2026 08:47 | D41: Finished | E41: Finished Nile Red | F41: Beite | G41: Sau | H41: 5.02 | I41: 0 | J41: 0 | L41: 0 | M41: 12.8 | N41: Klæbu | O41: Trondheim | P41: 10.49357 | Q41: 63.29473 | R41: Sauer, barnehage/hus, gjerde, skog
A42: Haugum Gård | B42: 15.1 | C42: 07.03.2026 08:36 | D42: Finished | E42: Finished Nile Red | F42: Korn | G42: Bygg | H42: 5 | I42: 2 | J42: 4 | L42: 0 | M42: 12.8 | N42: Klæbu | O42: Trondheim | P42: 10.47703 | Q42: 63.29292 | R42: Grusvei, hus? Høyspenningsmast rett over åker, litt trær
A43: Haugum Gård | B43: 15.2 | C43: 07.03.2026 08:43 | D43: Finished | E43: Finished Nile Red | F43: Korn | G43: Bygg | H43: 5 | I43: 0 | J43: 0 | L43: 0 | M43: 12.8 | N43: Klæbu | O43: Trondheim | P43: 10.47703 | Q43: 63.29292 | R43: Grusvei, hus? Høyspenningsmast rett over åker, litt trær
A44: Haugum Gård | B44: 15.3 | C44: 07.03.2026 08:54 | D44: Filtered | F44: Korn | G44: Bygg | H44: 5 | L44: 0 | M44: 12.8 | N44: Klæbu | O44: Trondheim | P44: 10.47703 | Q44: 63.29292 | R44: Grusvei, hus? Høyspenningsmast rett over åker, litt trær
A45: Stall Nidelv | B45: 16.1 | C45: 07.03.2026 09:26 | D45: Finished | E45: Finished Nile Red | F45: Gress | G45: Gress med deponi | H45: 5.01 | I45: 3 | J45: 3 | L45: 0 | M45: 12.8 | N45: Klæbu | O45: Trondheim | P45: 10.43968 | Q45: 63.29014 | R45: Skog med gris, trær, vei, Grusvei, hus/gård, høyspenningsmast
A46: Stall Nidelv | B46: 16.2 | C46: 07.03.2026 09:39 | D46: Finished | E46: Finished Nile Red | F46: Beite | G46: Gris | H46: 5.03 | I46: 1 | J46: 0 og 1 | L46: 0 | M46: 12.8 | N46: Klæbu | O46: Trondheim | P46: 10.43968 | Q46: 63.29014 | R46: Skog med gris, trær, vei, Grusvei, hus/gård, høyspenningsmast | T46: 16.2 B har 1
A47: Stall Nidelv | B47: 16.3 | C47: 07.03.2026 09:46 | D47: Finished | E47: Finished Nile Red | F47: Gress | G47: Gress | H47: 5.01 | I47: 1 | J47: 1 | L47: 0 | M47: 12.8 | N47: Klæbu | O47: Trondheim | P47: 10.43968 | Q47: 63.29014 | R47: Skog med gris, trær, vei, Grusvei, hus/gård, høyspenningsmast
A48: Stall Nidelv | B48: 16.4 | C48: 07.03.2026 09:25 | D48: Finished | E48: Finished Nile Red | F48: Beite | G48: Hest | H48: 5 | I48: 0 | J48: 0 | L48: 0 | M48: 12.8 | N48: Klæbu | O48: Trondheim | P48: 10.43968 | Q48: 63.29014 | R48: Skog med gris, trær, vei, Grusvei, hus/gård, høyspenningsmast
A49: Stall Nidelv | B49: 16.5 | C49: 07.03.2026 09:35 | D49: Finished | E49: Finished Nile Red | F49: Korn | G49: Bygg | H49: 5.03 | I49: 2 | J49: 2 | L49: 0 | M49: 12.8 | N49: Klæbu | O49: Trondheim | P49: 10.43968 | Q49: 63.29014 | R49: Skog med gris, trær, vei, Grusvei, hus/gård, høyspenningsmast
A50: Grønn Vekst | B50: 17.1 | C50: 07.03.2026 10:23 | D50: Finished | E50: Finished Nile Red | F50: Other | G50: Grønn Vekst Hagemix | H50: 5.02 | I50: 0 | J50: 0 | N50: Melhus | O50: Melhus | P50: 10.37534 | Q50: 63.3176 | R50: Jordplukk, grus, maskiner
...

Sheet Status
A1: Total Samples | B1: =SUM(B2:B9) -> 128
A2: Gathered | B2: =COUNTIF(Data!D:D,"Gathered") -> 0
A3: Tray | B3: =COUNTIF(Data!D:D,"Tray") -> 0
A4: Dryed | B4: =COUNTIF(Data!D:D,"Dryed") -> 0
A5: Sieved | B5: =COUNTIF(Data!D:D,"Sieved") -> 0
A6: Dissolved | B6: =COUNTIF(Data!D:D,"Dissolved") -> 0
A7: Filtered | B7: =COUNTIF(Data!D:D,"Filtered") -> 2
A8: Analysing | B8: =COUNTIF(Data!D:D,"Analysing") -> 0
A9: Finished | B9: =COUNTIF(Data!D:D,"Finished") -> 126
A11: Finished SIC | B11: =COUNTIF(Data!E:E,"Finished SIC") -> 0
A12: Finished Nile Red | B12: =COUNTIF(Data!E:E,"Finished Nile Red") -> 126

Sheet Lists
A1: Regions | C1: What is Produced | E1: Weather | G1: Status | I1: Kjøreplan | K1: Status Analysis | M1: Kommuner
A2: Trondheim | C2: Gress | E2: Sunny | G2: Gathered | I2: Trondheim | K2: Finished SIC | M2: Rindal
A3: Spongdal | C3: Beite | E3: Rainy | G3: Tray | I3: Spongdal | K3: Finished Nile Red | M3: Orkland
A4: Klæbu | C4: Korn | E4: Cloudy | G4: Dryed | I4: Klæbu | M4: Skaun
A5: Melhus | C5: Grønnsak | G5: Sieved | I5: Melhus | M5: Trondheim
A6: Frosta | C6: Frukt | G6: Dissolved | I6: Frosta | M6: Melhus
A7: Stjørdal | C7: Tobakk | G7: Filtered | I7: Stjørdal | M7: Selbu
A8: Rindal | C8: Other | G8: Analysing | I8: Rindal | M8: Malvik
A9: Selbu | G9: Finished | I9: Malvik | M9: Stjørdal
I10: Levanger | M10: Levanger
I11: Skaun | M11: Frosta
I12: Orkland
I13: Other
A14: Other

Sheet Analyse Område
B1: Trondheim | C1: Spongdal | D1: Klæbu | E1: Melhus | F1: Frosta | G1: Stjørdal | H1: Rindal | I1: Levanger | J1: Selbu | L1: {=TRANSPOSE(_xlfn.UNIQUE(_xlfn._xlws.FILTER(Data!O:O, Data!O:O<>"")))} -> Kommuner | M1: Trondheim | N1: Melhus | O1: Rindal | P1: Orkland | Q1: Skaun | R1: Levanger | S1: Frosta | T1: Stjørdal | U1: Selbu
A2: Sum | B2: =SUM(_xlfn.ANCHORARRAY(B5)) -> 2 | C2: =SUM(_xlfn.ANCHORARRAY(C5)) -> 32 | D2: =SUM(_xlfn.ANCHORARRAY(D5)) -> 17 | E2: =SUM(_xlfn.ANCHORARRAY(E5)) -> 31 | F2: =SUM(_xlfn.ANCHORARRAY(F5)) -> 16 | G2: =SUM(_xlfn.ANCHORARRAY(G5)) -> 5 | H2: =SUM(_xlfn.ANCHORARRAY(H5)) -> 25 | I2: =SUM(_xlfn.ANCHORARRAY(I5)) -> 12 | J2: =SUM(_xlfn.ANCHORARRAY(J5)) -> 14 | L2: Gjennomsnitt | M2: =AVERAGE(_xlfn.ANCHORARRAY(M7)) -> 1.1333333 | N2: =AVERAGE(_xlfn.ANCHORARRAY(N7)) -> 1.7222222 | O2: =AVERAGE(_xlfn.ANCHORARRAY(O7)) -> 1.8888889 | P2: =AVERAGE(_xlfn.ANCHORARRAY(P7)) -> 0.2 | Q2: =AVERAGE(_xlfn.ANCHORARRAY(Q7)) -> 1.75 | R2: =AVERAGE(_xlfn.ANCHORARRAY(R7)) -> 1 | S2: =AVERAGE(_xlfn.ANCHORARRAY(S7)) -> 1.7777778 | T2: =AVERAGE(_xlfn.ANCHORARRAY(T7)) -> 0.84615385 | U2: =AVERAGE(_xlfn.ANCHORARRAY(U7)) -> 0.72727273
A3: Gjennomsnitt | B3: =AVERAGE(_xlfn.ANCHORARRAY(B5)) -> 1 | C3: =AVERAGE(_xlfn.ANCHORARRAY(C5)) -> 1.3913043 | D3: =AVERAGE(_xlfn.ANCHORARRAY(D5)) -> 0.85 | E3: =AVERAGE(_xlfn.ANCHORARRAY(E5)) -> 1.7222222 | F3: =AVERAGE(_xlfn.ANCHORARRAY(F5)) -> 1.7777778 | G3: =AVERAGE(_xlfn.ANCHORARRAY(G5)) -> 1 | H3: =AVERAGE(_xlfn.ANCHORARRAY(H5)) -> 1.3888889 | I3: =AVERAGE(_xlfn.ANCHORARRAY(I5)) -> 1 | J3: =AVERAGE(_xlfn.ANCHORARRAY(J5)) -> 0.73684211 | L3: Median | M3: =MEDIAN(_xlfn.ANCHORARRAY(M7)) -> 1 | N3: =MEDIAN(_xlfn.ANCHORARRAY(N7)) -> 1 | O3: =MEDIAN(_xlfn.ANCHORARRAY(O7)) -> 1 | P3: =MEDIAN(_xlfn.ANCHORARRAY(P7)) -> 0 | Q3: =MEDIAN(_xlfn.ANCHORARRAY(Q7)) -> 1.5 | R3: =MEDIAN(_xlfn.ANCHORARRAY(R7)) -> 1 | S3: =MEDIAN(_xlfn.ANCHORARRAY(S7)) -> 2 | T3: =MEDIAN(_xlfn.ANCHORARRAY(T7)) -> 1 | U3: =MEDIAN(_xlfn.ANCHORARRAY(U7)) -> 0
A4: Median | B4: =MEDIAN(_xlfn.ANCHORARRAY(B5)) -> 1 | C4: =MEDIAN(_xlfn.ANCHORARRAY(C5)) -> 1 | D4: =MEDIAN(_xlfn.ANCHORARRAY(D5)) -> 0 | E4: =MEDIAN(_xlfn.ANCHORARRAY(E5)) -> 1 | F4: =MEDIAN(_xlfn.ANCHORARRAY(F5)) -> 2 | G4: =MEDIAN(_xlfn.ANCHORARRAY(G5)) -> 1 | H4: =MEDIAN(_xlfn.ANCHORARRAY(H5)) -> 1 | I4: =MEDIAN(_xlfn.ANCHORARRAY(I5)) -> 1 | J4: =MEDIAN(_xlfn.ANCHORARRAY(J5)) -> 0 | L4: Sum of plastic found | M4: =SUM(_xlfn.ANCHORARRAY(M7)) -> 51 | N4: =SUM(_xlfn.ANCHORARRAY(N7)) -> 31 | O4: =SUM(_xlfn.ANCHORARRAY(O7)) -> 17 | P4: =SUM(_xlfn.ANCHORARRAY(P7)) -> 1 | Q4: =SUM(_xlfn.ANCHORARRAY(Q7)) -> 7 | R4: =SUM(_xlfn.ANCHORARRAY(R7)) -> 12 | S4: =SUM(_xlfn.ANCHORARRAY(S7)) -> 16 | T4: =SUM(_xlfn.ANCHORARRAY(T7)) -> 11 | U4: =SUM(_xlfn.ANCHORARRAY(U7)) -> 8
B5: {=_xlfn._xlws.FILTER(Data!$I:$I,Data!$N:$N=B1)} -> 1 | C5: {=_xlfn._xlws.FILTER(Data!$I:$I,Data!$N:$N=C1)} -> 3 | D5: {=_xlfn._xlws.FILTER(Data!$I:$I,Data!$N:$N=D1)} -> 0 | E5: {=_xlfn._xlws.FILTER(Data!$I:$I,Data!$N:$N=E1)} -> 0 | F5: {=_xlfn._xlws.FILTER(Data!$I:$I,Data!$N:$N=F1)} -> 2 | G5: {=_xlfn._xlws.FILTER(Data!$I:$I,Data!$N:$N=G1)} -> 0 | H5: {=_xlfn._xlws.FILTER(Data!$I:$I,Data!$N:$N=H1)} -> 1 | I5: {=_xlfn._xlws.FILTER(Data!$I:$I,Data!$N:$N=I1)} -> 3 | J5: {=_xlfn._xlws.FILTER(Data!$I:$I,Data!$N:$N=J1)} -> 1 | L5: Count if yes | M5: =COUNTIF(_xlfn.ANCHORARRAY(M7),">0") -> 25 | N5: =COUNTIF(_xlfn.ANCHORARRAY(N7),">0") -> 15 | O5: =COUNTIF(_xlfn.ANCHORARRAY(O7),">0") -> 9 | P5: =COUNTIF(_xlfn.ANCHORARRAY(P7),">0") -> 1 | Q5: =COUNTIF(_xlfn.ANCHORARRAY(Q7),">0") -> 4 | R5: =COUNTIF(_xlfn.ANCHORARRAY(R7),">0") -> 7 | S5: =COUNTIF(_xlfn.ANCHORARRAY(S7),">0") -> 8 | T5: =COUNTIF(_xlfn.ANCHORARRAY(T7),">0") -> 7 | U5: =COUNTIF(_xlfn.ANCHORARRAY(U7),">0") -> 4
B6: 1 | C6: 3 | D6: 1 | E6: 1 | F6: 2 | G6: 1 | H6: 1 | I6: 2 | J6: 1 | L6: Total | M6: =COUNT(_xlfn.ANCHORARRAY(M7)) -> 45 | N6: =COUNT(_xlfn.ANCHORARRAY(N7)) -> 18 | O6: =COUNT(_xlfn.ANCHORARRAY(O7)) -> 9 | P6: =COUNT(_xlfn.ANCHORARRAY(P7)) -> 5 | Q6: =COUNT(_xlfn.ANCHORARRAY(Q7)) -> 4 | R6: =COUNT(_xlfn.ANCHORARRAY(R7)) -> 12 | S6: =COUNT(_xlfn.ANCHORARRAY(S7)) -> 9 | T6: =COUNT(_xlfn.ANCHORARRAY(T7)) -> 13 | U6: =COUNT(_xlfn.ANCHORARRAY(U7)) -> 11
C7: 5 | D7: 5 | E7: 4 | F7: 2 | G7: 3 | H7: 5 | I7: 2 | J7: 3 | M7: {=_xlfn._xlws.FILTER(Data!$I:$I,Data!$O:$O=M1)} -> 1 | N7: {=_xlfn._xlws.FILTER(Data!$I:$I,Data!$O:$O=N1)} -> 0 | O7: {=_xlfn._xlws.FILTER(Data!$I:$I,Data!$O:$O=O1)} -> 1 | P7: {=_xlfn._xlws.FILTER(Data!$I:$I,Data!$O:$O=P1)} -> 0 | Q7: {=_xlfn._xlws.FILTER(Data!$I:$I,Data!$O:$O=Q1)} -> 2 | R7: {=_xlfn._xlws.FILTER(Data!$I:$I,Data!$O:$O=R1)} -> 3 | S7: {=_xlfn._xlws.FILTER(Data!$I:$I,Data!$O:$O=S1)} -> 2 | T7: {=_xlfn._xlws.FILTER(Data!$I:$I,Data!$O:$O=T1)} -> 0 | U7: {=_xlfn._xlws.FILTER(Data!$I:$I,Data!$O:$O=U1)} -> 0
C8: 2 | D8: 0 | E8: 1 | F8: 2 | G8: 0 | H8: 1 | I8: 0 | J8: 0 | M8: 1 | N8: 1 | O8: 1 | P8: 0 | Q8: 1 | R8: 2 | S8: 2 | T8: 1 | U8: 2
C9: 0 | D9: 0 | E9: 1 | F9: 0 | G9: 1 | H9: 1 | I9: 0 | J9: 0 | M9: 3 | N9: 4 | O9: 5 | P9: 0 | Q9: 1 | R9: 2 | S9: 2 | T9: 3 | U9: 0
C10: 2 | D10: 0 | E10: 4 | F10: 3 | H10: 1 | I10: 2 | J10: 1 | M10: 3 | N10: 1 | O10: 1 | P10: 1 | Q10: 3 | R10: 0 | S10: 2 | T10: 0 | U10: 1
C11: 0 | D11: 1 | E11: 3 | F11: 1 | H11: 2 | I11: 1 | J11: 0 | M11: 5 | N11: 1 | O11: 1 | P11: 0 | R11: 0 | S11: 0 | T11: 1 | U11: 0
C12: 1 | D12: 0 | E12: 1 | F12: 1 | H12: 1 | I12: 0 | J12: 0 | M12: 2 | N12: 4 | O12: 1 | R12: 2 | S12: 3 | T12: 1 | U12: 0
C13: 3 | D13: 0 | E13: 2 | F13: 3 | H13: 4 | I13: 0 | J13: 0 | M13: 0 | N13: 3 | O13: 2 | R13: 1 | S13: 1 | T13: 1 | U13: 3
C14: 2 | D14: 0 | E14: 3 | H14: 0 | I14: 1 | J14: 2 | M14: 2 | N14: 1 | O14: 1 | R14: 0 | S14: 1 | T14: 3 | U14: 0
C15: 2 | D15: 1 | E15: 2 | H15: 0 | I15: 0 | J15: 0 | M15: 0 | N15: 2 | O15: 4 | R15: 0 | S15: 3 | T15: 0 | U15: 0
C16: 3 | D16: 0 | E16: 1 | H16: 0 | I16: 1 | J16: 1 | M16: 1 | N16: 3 | R16: 1 | T16: 0 | U16: 2
C17: 0 | D17: 2 | E17: 0 | H17: 1 | J17: 0 | M17: 3 | N17: 2 | R17: 0 | T17: 1 | U17: 0
C18: 0 | D18: 0 | E18: 1 | H18: 0 | J18: 0 | M18: 2 | N18: 1 | R18: 1 | T18: 0
C19: 0 | D19: 0 | E19: 4 | H19: 2 | J19: 3 | M19: 2 | N19: 0 | T19: 0
C20: 0 | D20: 3 | E20: 1 | H20: 1 | J20: 0 | M20: 3 | N20: 1
C21: 1 | D21: 1 | E21: 2 | H21: 1 | J21: 0 | M21: 0 | N21: 4
C22: 0 | D22: 1 | E22: 0 | H22: 3 | J22: 2 | M22: 0 | N22: 1 | W22: Kommune | X22: Antall prøver | Y22: Antall totale mikroplastpartikler | Z22: Gjennomsnittlig antall mikroplastpartikler
C23: 1 | D23: 0 | J23: 0 | M23: 0 | N23: 2 | W23: Trondheim | X23: 45 | Y23: =M4 -> 51 | Z23: =Y23/X23 -> 1.1333333
C24: 1 | D24: 2 | M24: 0 | N24: 0 | W24: Melhus | X24: 18 | Y24: =N4 -> 31 | Z24: =Y24/X24 -> 1.7222222
C25: 0 | M25: 1 | W25: Rindal | X25: 9 | Y25: =O4 -> 17 | Z25: =Y25/X25 -> 1.8888889
C26: 3 | M26: 0 | W26: Orkland | X26: 5 | Y26: =P4 -> 1 | Z26: =Y26/X26 -> 0.2
C27: 0 | M27: 1 | W27: Skaun | X27: 4 | Y27: =Q4 -> 7 | Z27: =Y27/X27 -> 1.75
M28: 1 | W28: Levanger | X28: 12 | Y28: =R4 -> 12 | Z28: =Y28/X28 -> 1
M29: 0 | W29: Frosta | X29: 9 | Y29: =S4 -> 16 | Z29: =Y29/X29 -> 1.7777778
M30: 3 | W30: Stjørdal | X30: 13 | Y30: =T4 -> 11 | Z30: =Y30/X30 -> 0.84615385
M31: 0 | W31: Selbu | X31: 11 | Y31: =U4 -> 8 | Z31: =Y31/X31 -> 0.72727273
M32: 0
M33: 1
M34: 5
M35: 0
M36: 0
M37: 0
M38: 1
M39: 0
M40: 0
...

Sheet Analyse What is Produced
B1: Gress | C1: Beite | D1: Korn | E1: Grønnsak | F1: Frukt | G1: Annet | T1: {=TRANSPOSE(_xlfn.UNIQUE(_xlfn._xlws.FILTER(Data!G:G, Data!G:G<>"")))} -> What is produced spesific | U1: Gress | V1: Geit | W1: Sau | X1: Bygg | Y1: Korn | Z1: Tobakk | AA1: Frimark | AB1: Ku | AC1: Potet | AD1: Gress (poteter for 4 år siden) | AE1: Bringebær | AF1: Jordbær | AG1: Havre | AH1: Pose med jord | AI1: Jord fra planter man kan kjøpe: Eple, Rabarbara, Hageblåbær, Bringebær, Rips, Kruspersille, Citronmelisse, Timian, Rosmarin, Snack Paprika, Rød Chili, Cherry tomat, cocktailtomat | AJ1: Gress på myr | AK1: Hest | AL1: Skogsjord | AM1: Gress med deponi | AN1: Gris | AO1: Grønn Vekst Hagemix | AP1: Lagring av Høyballer | AQ1: Hvete | AR1: Kål | AS1: Brokolini | AT1: Gulrot | AU1: Pære | AV1: Allerede høsta potet | AW1: Many things, noncommercial | AX1: Sau, Ku | AY1: Eple | AZ1: Alpakka
A2: Sum | B2: =SUM(_xlfn.ANCHORARRAY(B5)) -> 61 | C2: =SUM(_xlfn.ANCHORARRAY(C5)) -> 25 | D2: =SUM(_xlfn.ANCHORARRAY(D5)) -> 47 | E2: =SUM(_xlfn.ANCHORARRAY(E5)) -> 10 | F2: =SUM(_xlfn.ANCHORARRAY(F5)) -> 7 | G2: =SUM(_xlfn.ANCHORARRAY(G5)) -> 17 | T2: Sum | U2: =SUM(_xlfn.ANCHORARRAY(U5)) -> 56 | V2: =SUM(_xlfn.ANCHORARRAY(V5)) -> 1 | W2: =SUM(_xlfn.ANCHORARRAY(W5)) -> 7 | X2: =SUM(_xlfn.ANCHORARRAY(X5)) -> 22 | Y2: =SUM(_xlfn.ANCHORARRAY(Y5)) -> 4 | Z2: =SUM(_xlfn.ANCHORARRAY(Z5)) -> 3 | AA2: =SUM(_xlfn.ANCHORARRAY(AA5)) -> 0 | AB2: =SUM(_xlfn.ANCHORARRAY(AB5)) -> 11 | ... AZ2: =SUM(_xlfn.ANCHORARRAY(AZ5)) -> 3
A3: Gjennomsnitt | B3: =AVERAGE(_xlfn.ANCHORARRAY(B5)) -> 1.3863636 | C3: =AVERAGE(_xlfn.ANCHORARRAY(C5)) -> 1.1904762 | D3: =AVERAGE(_xlfn.ANCHORARRAY(D5)) -> 1.2368421 | E3: =AVERAGE(_xlfn.ANCHORARRAY(E5)) -> 0.76923077 | F3: =AVERAGE(_xlfn.ANCHORARRAY(F5)) -> 1.4 | G3: =AVERAGE(_xlfn.ANCHORARRAY(G5)) -> 2.8333333 | T3: Gjennomsnitt | U3: =AVERAGE(_xlfn.ANCHORARRAY(U5)) -> 1.4358974 | V3: =AVERAGE(_xlfn.ANCHORARRAY(V5)) -> 1 | W3: =AVERAGE(_xlfn.ANCHORARRAY(W5)) -> 1.4 | X3: =AVERAGE(_xlfn.ANCHORARRAY(X5)) -> 0.91666667 | Y3: =AVERAGE(_xlfn.ANCHORARRAY(Y5)) -> 1.3333333 | Z3: =AVERAGE(_xlfn.ANCHORARRAY(Z5)) -> 3 | AA3: =AVERAGE(_xlfn.ANCHORARRAY(AA5)) -> 0 | AB3: =AVERAGE(_xlfn.ANCHORARRAY(AB5)) -> 1.5714286 | ... AZ3: =AVERAGE(_xlfn.ANCHORARRAY(AZ5)) -> 1
A4: Median | B4: =MEDIAN(_xlfn.ANCHORARRAY(B5)) -> 1 | C4: =MEDIAN(_xlfn.ANCHORARRAY(C5)) -> 1 | D4: =MEDIAN(_xlfn.ANCHORARRAY(D5)) -> 1 | E4: =MEDIAN(_xlfn.ANCHORARRAY(E5)) -> 0 | F4: =MEDIAN(_xlfn.ANCHORARRAY(F5)) -> 1 | G4: =MEDIAN(_xlfn.ANCHORARRAY(G5)) -> 0.5 | T4: Median | U4: =MEDIAN(_xlfn.ANCHORARRAY(U5)) -> 1 | V4: =MEDIAN(_xlfn.ANCHORARRAY(V5)) -> 1 | W4: =MEDIAN(_xlfn.ANCHORARRAY(W5)) -> 1 | X4: =MEDIAN(_xlfn.ANCHORARRAY(X5)) -> 0 | Y4: =MEDIAN(_xlfn.ANCHORARRAY(Y5)) -> 2 | Z4: =MEDIAN(_xlfn.ANCHORARRAY(Z5)) -> 3 | AA4: =MEDIAN(_xlfn.ANCHORARRAY(AA5)) -> 0 | AB4: =MEDIAN(_xlfn.ANCHORARRAY(AB5)) -> 1 | ... AZ4: =MEDIAN(_xlfn.ANCHORARRAY(AZ5)) -> 1
B5: {=_xlfn._xlws.FILTER(Data!$I:$I,Data!$F:$F=B1)} -> 1 | C5: {=_xlfn._xlws.FILTER(Data!$I:$I,Data!$F:$F=C1)} -> 1 | D5: {=_xlfn._xlws.FILTER(Data!$I:$I,Data!$F:$F=D1)} -> 5 | E5: {=_xlfn._xlws.FILTER(Data!$I:$I,Data!$F:$F=E1)} -> 0 | F5: {=_xlfn._xlws.FILTER(Data!$I:$I,Data!$F:$F=F1)} -> 1 | G5: {=_xlfn._xlws.FILTER(Data!$I:$I,Data!$F:$F="Other")} -> 3 | U5: {=_xlfn._xlws.FILTER(Data!$I:$I,Data!$G:$G=U1)} -> 1 | V5: {=_xlfn._xlws.FILTER(Data!$I:$I,Data!$G:$G=V1)} -> 1 | W5: {=_xlfn._xlws.FILTER(Data!$I:$I,Data!$G:$G=W1)} -> 3 | X5: {=_xlfn._xlws.FILTER(Data!$I:$I,Data!$G:$G=X1)} -> 5 | Y5: {=_xlfn._xlws.FILTER(Data!$I:$I,Data!$G:$G=Y1)} -> 2 | Z5: {=_xlfn._xlws.FILTER(Data!$I:$I,Data!$G:$G=Z1)} -> 3 | AA5: {=_xlfn._xlws.FILTER(Data!$I:$I,Data!$G:$G=AA1)} -> 0 | AB5: {=_xlfn._xlws.FILTER(Data!$I:$I,Data!$G:$G=AB1)} -> 1 | ... AZ5: {=_xlfn._xlws.FILTER(Data!$I:$I,Data!$G:$G=AZ1)} -> 2
B6: 3 | C6: 3 | D6: 3 | E6: 0 | F6: 0 | G6: 0 | U6: 3 | W6: 0 | X6: 3 | Y6: 0 | AB6: 1 | AC6: 0 | AE6: 3 | AG6: 3 | AK6: 0 | AL6: 1 | AQ6: 3 | AT6: 0 | AZ6: 0
B7: 2 | C7: 1 | D7: 2 | E7: 0 | F7: 2 | G7: 13 | U7: 2 | W7: 0 | X7: 2 | Y7: 2 | AB7: 1 | AC7: 0 | AG7: 2 | AK7: 1 | AQ7: 2 | AZ7: 1
B8: 0 | C8: 0 | D8: 2 | E8: 2 | F8: 1 | G8: 0 | U8: 0 | W8: 1 | X8: 0 | AB8: 2 | AC8: 1 | AG8: 0 | AQ8: 2
B9: 2 | C9: 0 | D9: 0 | E9: 0 | F9: 3 | G9: 0 | U9: 2 | W9: 3 | X9: 0 | AB9: 1 | AC9: 1 | AG9: 3
B10: 0 | C10: 1 | D10: 0 | E10: 0 | G10: 1 | U10: 0 | X10: 0 | AB10: 4 | AC10: 2 | AG10: 1
B11: 1 | C11: 0 | D11: 0 | E11: 1 | U11: 1 | X11: 0 | AB11: 1 | AC11: 2 | AG11: 0
B12: 1 | C12: 1 | D12: 3 | E12: 0 | U12: 0 | X12: 0
B13: 0 | C13: 1 | D13: 0 | E13: 1 | U13: 1 | X13: 1
B14: 1 | C14: 2 | D14: 0 | E14: 2 | U14: 5 | X14: 2
B15: 5 | C15: 1 | D15: 0 | E15: 2 | U15: 0 | X15: 0
B16: 0 | C16: 4 | D16: 1 | E16: 2 | U16: 1 | X16: 0
B17: 0 | C17: 1 | D17: 2 | E17: 0 | U17: 5 | X17: 2
B18: 0 | C18: 1 | D18: 0 | U18: 1 | X18: 0
B19: 1 | C19: 1 | D19: 0 | U19: 1 | X19: 0
B20: 3 | C20: 0 | D20: 2 | U20: 1 | X20: 1
B21: 1 | C21: 1 | D21: 0 | U21: 1 | X21: 3
B22: 5 | C22: 3 | D22: 0 | U22: 1 | X22: 1
B23: 1 | C23: 2 | D23: 2 | U23: 3 | X23: 0
B24: 1 | C24: 0 | D24: 3 | U24: 1 | X24: 0
B25: 1 | C25: 1 | D25: 1 | U25: 4 | X25: 0
B26: 1 | D26: 2 | U26: 1 | X26: 1
B27: 1 | D27: 3 | U27: 4 | X27: 1
B28: 3 | D28: 1 | U28: 2 | X28: 0
B29: 1 | D29: 2 | U29: 1
B30: 4 | D30: 0 | U30: 0
B31: 1 | D31: 3 | U31: 4
B32: 4 | D32: 2 | U32: 1
B33: 2 | D33: 2 | U33: 3
B34: 1 | D34: 0 | U34: 0
B35: 0 | D35: 0 | U35: 0
B36: 4 | D36: 0 | U36: 1
B37: 1 | D37: 1 | U37: 0
B38: 3 | D38: 3 | U38: 0
B39: 0 | D39: 1 | U39: 0
B40: 0 | D40: 1 | U40: 0
...

Sheet Sheet2
B1: Gress | C1: Beite | D1: Korn | E1: Grønnsak | F1: Frukt | G1: Annet
A2: Sum | B2: 61 | C2: 25 | D2: 47 | E2: 10 | F2: 7 | G2: =SUM(G5:G9) -> 4
A3: Gjennomsnitt | B3: 1.3863636 | C3: 1.1904762 | D3: 1.2368421 | E3: 0.76923077 | F3: 1.4 | G3: =AVERAGE(G5:G9) -> 0.8
A4: Median | B4: 1 | C4: 1 | D4: 1 | E4: 0 | F4: 1 | G4: =MEDIAN(G5:G9) -> 0
B5: 1 | C5: 1 | D5: 5 | E5: 0 | F5: 1 | G5: 3
B6: 3 | C6: 3 | D6: 3 | E6: 0 | F6: 0 | G6: 0
B7: 2 | C7: 1 | D7: 2 | E7: 0 | F7: 2 | G7: 0
B8: 0 | C8: 0 | D8: 2 | E8: 2 | F8: 1 | G8: 0
B9: 2 | C9: 0 | D9: 0 | E9: 0 | F9: 3 | G9: 1
B10: 0 | C10: 1 | D10: 0 | E10: 0
B11: 1 | C11: 0 | D11: 0 | E11: 1
B12: 1 | C12: 1 | D12: 3 | E12: 0
B13: 0 | C13: 1 | D13: 0 | E13: 1
B14: 1 | C14: 2 | D14: 0 | E14: 2
B15: 5 | C15: 1 | D15: 0 | E15: 2
B16: 0 | C16: 4 | D16: 1 | E16: 2
B17: 0 | C17: 1 | D17: 2 | E17: 0
B18: 0 | C18: 1 | D18: 0
B19: 1 | C19: 1 | D19: 0
B20: 3 | C20: 0 | D20: 2
B21: 1 | C21: 1 | D21: 0
B22: 5 | C22: 3 | D22: 0
B23: 1 | C23: 2 | D23: 2
B24: 1 | C24: 0 | D24: 3
B25: 1 | C25: 1 | D25: 1
B26: 1 | D26: 2
B27: 1 | D27: 3
B28: 3 | D28: 1
B29: 1 | D29: 2
B30: 4 | D30: 0
B31: 1 | D31: 3
B32: 4 | D32: 2
B33: 2 | D33: 2
B34: 1 | D34: 0
B35: 0 | D35: 0
B36: 4 | D36: 0
B37: 1 | D37: 1
... B42: 0 | D42: 0
B43: 0
B44: 0
...

Sheet Analyse Gård
B1: {=TRANSPOSE(_xlfn.UNIQUE(_xlfn._xlws.FILTER(Data!A:A, Data!A:A<>"")))} -> Name of Farm | C1: Voll Gård | D1: Onsøyen Gård | E1: Frøset Østre | F1: Hangerslettvegen 605 | G1: Ålberg Gård | H1: Snusbonden | I1: Lerdal Øvre | J1: Kviset Gård | K1: Spongdalsvegen 473 (oppland gård) | L1: Plantasjen | M1: Leander Lysklett | N1: Vangsmo | O1: Christine Bertelsen | P1: Jonettaplassen Gårdsbarnehage | Q1: Haugum Gård | R1: Stall Nidelv | S1: Grønn Vekst | T1: Rindalslina 712 | U1: Halgunsetvegen 117 | V1: NABO Halgunsetvegen 117 | W1: Solhus gård | X1: Aunbygdvegen 40 | Y1: Øver Bortn Gård | Z1: Rofstadbakken | AA1: Gislaug Loddgård | AB1: Dalan gård | AC1: Skarsem gård | AD1: Nordtømmesvegen 151 | AE1: Røstad øvre | AF1: Håa gård | AG1: Fostad nordre | AH1: Søstrene Moksnes | AI1: Myraunet gård | AJ1: Hellberg gård | AK1: Ola Fiskvik | AL1: Kindseth gård | AM1: Julseth østre | AN1: Brennmoen gård | AO1: Rolset sag | AP1: Alpakkalia | AQ1: Berge gård
A2: Gjennomsnitt | B2: =AVERAGE(C2:AQ2) -> 1.3084785 | C2: =AVERAGE(_xlfn.ANCHORARRAY(C4)) -> 1 | D2: =AVERAGE(_xlfn.ANCHORARRAY(D4)) -> 3.25 | E2: =AVERAGE(_xlfn.ANCHORARRAY(E4)) -> 1 | F2: =AVERAGE(_xlfn.ANCHORARRAY(F4)) -> 0.5 | G2: =AVERAGE(_xlfn.ANCHORARRAY(G4)) -> 2.5 | H2: =AVERAGE(_xlfn.ANCHORARRAY(H4)) -> 1.6666667 | I2: =AVERAGE(_xlfn.ANCHORARRAY(I4)) -> 0 | J2: =AVERAGE(_xlfn.ANCHORARRAY(J4)) -> 0.66666667 | ... AQ2: =AVERAGE(_xlfn.ANCHORARRAY(AQ4)) -> 0.71428571
A3: Sum | B3: =SUM(C3:AQ3) -> 167 | C3: =SUM(_xlfn.ANCHORARRAY(C4)) -> 2 | D3: =SUM(_xlfn.ANCHORARRAY(D4)) -> 13 | E3: =SUM(_xlfn.ANCHORARRAY(E4)) -> 2 | F3: =SUM(_xlfn.ANCHORARRAY(F4)) -> 1 | G3: =SUM(_xlfn.ANCHORARRAY(G4)) -> 5 | H3: =SUM(_xlfn.ANCHORARRAY(H4)) -> 5 | I3: =SUM(_xlfn.ANCHORARRAY(I4)) -> 0 | J3: =SUM(_xlfn.ANCHORARRAY(J4)) -> 2 | ... AQ3: =SUM(_xlfn.ANCHORARRAY(AQ4)) -> 5
C4: {=_xlfn._xlws.FILTER(Data!$I:$I,Data!$A:$A=C1)} -> 1 | D4: {=_xlfn._xlws.FILTER(Data!$I:$I,Data!$A:$A=D1)} -> 3 | E4: {=_xlfn._xlws.FILTER(Data!$I:$I,Data!$A:$A=E1)} -> 0 | F4: {=_xlfn._xlws.FILTER(Data!$I:$I,Data!$A:$A=F1)} -> 0 | G4: {=_xlfn._xlws.FILTER(Data!$I:$I,Data!$A:$A=G1)} -> 3 | H4: {=_xlfn._xlws.FILTER(Data!$I:$I,Data!$A:$A=H1)} -> 2 | I4: {=_xlfn._xlws.FILTER(Data!$I:$I,Data!$A:$A=I1)} -> 0 | J4: {=_xlfn._xlws.FILTER(Data!$I:$I,Data!$A:$A=J1)} -> 1 | ... AQ4: {=_xlfn._xlws.FILTER(Data!$I:$I,Data!$A:$A=AQ1)} -> 0
C5: 1 | D5: 3 | E5: 2 | F5: 1 | G5: 2 | H5: 3 | I5: 0 | J5: 0 | K5: 0 | L5: 0 | M5: 1 | N5: 0 | O5: 0 | Q5: 0 | R5: 1 | T5: 1 | U5: 1 | W5: 0 | X5: 1 | Y5: 4 | Z5: 4 | AA5: 2 | AB5: 1 | AC5: 4 | AE5: 2 | AF5: 0 | AG5: 1 | AH5: 2 | AI5: 3 | AJ5: 1 | AK5: 1 | AL5: 1 | AM5: 1 | AN5: 0 | AP5: 0 | AQ5: 0
D6: 5 | H6: 0 | I6: 0 | J6: 1 | K6: 3 | M6: 5 | N6: 1 | O6: 1 | Q6: 0 | R6: 1 | T6: 5 | U6: 2 | W6: 0 | X6: 1 | Y6: 1 | Z6: 3 | AA6: 3 | AB6: 0 | AC6: 1 | AE6: 2 | AF6: 0 | AH6: 2 | AJ6: 3 | AK6: 3 | AM6: 3 | AN6: 0 | AP6: 1 | AQ6: 3
D7: 2 | K7: 0 | M7: 0 | N7: 0 | R7: 0 | T7: 1 | U7: 1 | W7: 1 | X7: 3 | AC7: 2 | AE7: 0 | AF7: 1 | AH7: 2 | AM7: 0 | AQ7: 0
R8: 2 | W8: 0 | AE8: 0 | AM8: 0 | AQ8: 0
AE9: 2 | AQ9: 2
AQ10: 0
